Workbook

Sheet Dashboard
A1: CLEANSLATE CLEANING CO.
A2: Executive Dashboard
A4: Total Jobs | C4: Total Revenue | E4: Amount Collected | G4: Collection Rate | I4: Avg Job Value | K4: Total Customers
A5: =KPIs_Insights!A6 -> 7500 | C5: =KPIs_Insights!E6 -> 1655849.3 | E5: =KPIs_Insights!G6 -> 1356106.5 | G5: =Client_Summary!K6 -> 0.81897939 | I5: =KPIs_Insights!I6 -> 220.8388 | K5: =KPIs_Insights!C6 -> 1200
A8: BUSINESS PERFORMANCE
A24: MONTHLY TREND INPUT
A25: Month | B25: Revenue | C25: Jobs
A26: Jan | B26: =VLOOKUP(A26, Analysis!$G$19:$I$33, 2, FALSE) -> 144246.44 | C26: =VLOOKUP(A26, Analysis!$G$19:$I$33, 3, FALSE) -> 653
A27: Feb | B27: =VLOOKUP(A27, Analysis!$G$19:$I$33, 2, FALSE) -> 118524.61 | C27: =VLOOKUP(A27, Analysis!$G$19:$I$33, 3, FALSE) -> 561
A28: Mar | B28: =VLOOKUP(A28, Analysis!$G$19:$I$33, 2, FALSE) -> 135270.13 | C28: =VLOOKUP(A28, Analysis!$G$19:$I$33, 3, FALSE) -> 612
A29: Apr | B29: =VLOOKUP(A29, Analysis!$G$19:$I$33, 2, FALSE) -> 126297.71 | C29: =VLOOKUP(A29, Analysis!$G$19:$I$33, 3, FALSE) -> 570
A30: May | B30: =VLOOKUP(A30, Analysis!$G$19:$I$33, 2, FALSE) -> 140173.64 | C30: =VLOOKUP(A30, Analysis!$G$19:$I$33, 3, FALSE) -> 635
A31: Jun | B31: =VLOOKUP(A31, Analysis!$G$19:$I$33, 2, FALSE) -> 133053.46 | C31: =VLOOKUP(A31, Analysis!$G$19:$I$33, 3, FALSE) -> 604
A32: Jul | B32: =VLOOKUP(A32, Analysis!$G$19:$I$33, 2, FALSE) -> 141062.85 | C32: =VLOOKUP(A32, Analysis!$G$19:$I$33, 3, FALSE) -> 664
A33: Aug | B33: =VLOOKUP(A33, Analysis!$G$19:$I$33, 2, FALSE) -> 142881.82 | C33: =VLOOKUP(A33, Analysis!$G$19:$I$33, 3, FALSE) -> 648
A34: Sep | B34: =VLOOKUP(A34, Analysis!$G$19:$I$33, 2, FALSE) -> 139121.28 | C34: =VLOOKUP(A34, Analysis!$G$19:$I$33, 3, FALSE) -> 616
A35: Oct | B35: =VLOOKUP(A35, Analysis!$G$19:$I$33, 2, FALSE) -> 147473.61 | C35: =VLOOKUP(A35, Analysis!$G$19:$I$33, 3, FALSE) -> 655
A36: Nov | B36: =VLOOKUP(A36, Analysis!$G$19:$I$33, 2, FALSE) -> 142620.39 | C36: =VLOOKUP(A36, Analysis!$G$19:$I$33, 3, FALSE) -> 645
A37: Dec | B37: =VLOOKUP(A37, Analysis!$G$19:$I$33, 2, FALSE) -> 144488.67 | C37: =VLOOKUP(A37, Analysis!$G$19:$I$33, 3, FALSE) -> 635
A38: PAYMENT & DATA HEALTH
A39: Payment Status | B39: Jobs | C39: Amount Paid
A40: Paid | B40: =VLOOKUP(Dashboard!A40, KPIs_Insights!$I$12:$K$14, 2, FALSE) -> 5388 | C40: =VLOOKUP(Dashboard!A40, KPIs_Insights!$I$12:$K$14, 3, FALSE) -> 1190506 | E40: OVERALL DATA HEALTH Ready for Analysis
A41: Partial | B41: =VLOOKUP(Dashboard!A41, KPIs_Insights!$I$12:$K$14, 2, FALSE) -> 1373 | C41: =VLOOKUP(Dashboard!A41, KPIs_Insights!$I$12:$K$14, 3, FALSE) -> 165504.53
A42: Unpaid | B42: =VLOOKUP(Dashboard!A42, KPIs_Insights!$I$12:$K$14, 2, FALSE) -> 739 | C42: =VLOOKUP(Dashboard!A42, KPIs_Insights!$I$12:$K$14, 3, FALSE) -> 95.94
A53: Prepared for: | B53: CleanSlate Cleaning Co.
A54: Prepared by: | B54: Nigar Sultana
A55: Engagement | B55: Tier 3 — BI Reporting Package
A56: Report Date | B56: October 2026

Sheet Client_Summary
A1: CLEANSLATE CLEANING CO.
A2: Data Health & Business Snapshot
A4: OVERALL DATA HEALTH & KEY METRICS
A5: STATUS: READY FOR ANALYSIS | G5: Total Jobs | I5: Total Revenue | K5: Collection Rate
G6: =KPIs_Insights!A6 -> 7500 | I6: =KPIs_Insights!E6 -> 1655849.3 | K6: =KPIs_Insights!G6/KPIs_Insights!E6 -> 0.81897939
G9: Avg Job Value | I9: Total Customers
G10: =KPIs_Insights!I6 -> 220.8388 | I10: =KPIs_Insights!C6 -> 1200
A14: KEY FINDINGS
A15: 01 | B15: Post-Construction Clean is the strongest revenue-generating service. Generated approximately $457,782, representing 27.6% of total invoiced revenue across 1,273 jobs.
A16: 02 | B16: Recurring Clean has high job volume but relatively low revenue per job. Generated approximately $134,635 across 1,193 jobs, with an average invoiced revenue of approximately $113 per job.
A17: 03 | B17: Leander is the strongest service area. Generated approximately $285,533 in invoiced revenue across 1,291 jobs, leading all service areas in both revenue and job volume.
A18: 04 | B18: A significant portion of invoiced revenue has not been recorded as paid. $1.356M is recorded as paid against $1.656M invoiced, representing an 81.9% collection rate. The dataset includes 1,373 partially paid and 739 unpaid jobs.
A19: 05 | B19: The customer base shows strong repeat activity. 1,182 of 1,200 customers (98.5%) have more than one recorded job.
A22: RECOMMENDATIONS
A23: 01 | B23: Review pricing and service economics for Recurring Clean. Evaluate pricing, service scope, and labor requirements to determine whether the relatively low revenue per job adequately supports the workload generated by this service.
A24: 02 | B24: Prioritize follow-up on partial and unpaid invoices. Review the 1,373 partially paid and 739 unpaid jobs, while reconciling the identified payment-status inconsistencies before using the results for accounting decisions.
A25: 03 | B25: Focus growth and capacity planning on proven areas of demand. Consider the strong performance of Post-Construction Clean and the Leander service area when evaluating marketing, staffing, capacity, and future growth opportunities.

Sheet Client_Brief
A1: CLEANSLATE CLEANING CO.
A2: BI Reporting Package
A4: CLIENT REQUEST
A5: We have a few spreadsheets containing our customer and job information. Please check the data, clean up anything that is unreliable, and tell us what the data says about the business.
A7: QUESTIONS WE ARE TESTING
A8: 1. Is the raw dataset complete and internally consistent?
A9: 2. What data-quality issues need to be corrected or flagged?
A10: 3. Are there duplicate, missing, invalid, inconsistent, or contradictory records?
A11: 4. After cleaning, how many valid jobs and customers are represented?
A12: 5. What are the core KPIs — revenue, jobs, average job value, hours, and payment collection?
A13: 6. Which services generate the most revenue and/or job volume?
A14: 7. Which service areas or cleaners show meaningful differences in activity or performance?
... A23: This sample intentionally represents a larger Tier 1 engagement: approximately 7,500 job records plus supporting customer and service data. The goal is efficient data health and insight work—not a full BI implementation.

Sheet Validation_Reconciliation
A1: CLEANSLATE CLEANING CO.
A2: Validation & Reconciliation Control Sheet
A4: RECONCILIATION CONTROLS
A5: Control | B5: Source / Comparison | C5: Expected | D5: Actual | E5: Variance | F5: Status | G5: Formula / Method | H5: Notes
A6: Raw Jobs vs Clean Jobs | B6: Jobs_Raw → Jobs_Clean | C6: 7500 | D6: 7500 | E6: 0 | F6: PASS | G6: =ROWS(Jobs_Raw[Job ID]) and =ROWS(Jobs_Clean[Job ID])
A7: Raw Customers vs Clean Customers | B7: Customers_Raw → Customers_Clean | C7: 1200 | D7: 1200 | E7: 0 | F7: PASS | G7: =ROWS(Customers_Raw[Client ID]) and =ROWS(Customers_Clean[Client ID])
A8: Unique Job IDs | B8: Jobs_Raw | C8: 7500 | D8: =C8-4 -> 7496 | E8: =C8-D8 -> 4 | F8: FLAGGED | G8: =COUNTIF(Jobs_Clean[Job ID],[@[Job ID]]) | H8: 4 Job IDs occur more than once. Duplicate records contain different details and were retained for client review.
A9: Valid Client IDs | B9: Customers_Raw | C9: 7496 | D9: 7496 | E9: =C9-D9 -> 0 | F9: PASS | G9: COUNTIF / XLOOKUP / merge
A10: Missing Client IDs | B10: Jobs_Raw → Jobs_Clean | C10: 0 | D10: 5 | E10: 5 | F10: FLAGGED | G10: =COUNTBLANK(Jobs_Clean[Client ID]) | H10: 5 job records have no Client ID; records retained.
A11: Orphan Client IDs | B11: Jobs_Raw → Jobs_Clean | C11: 0 | D11: 0 | E11: 0 | F11: PASS | G11: =IF([@[Client ID]]="","MISSING",IF(COUNTIF(Customers_Clean[Client ID],[@[Client ID]])=0,"ORPHAN","OK")) | H11: All nonblank Client IDs match the customer master
A12: Invoice Total | B12: Jobs_Raw → Jobs_Clean | C12: =SUM(Jobs_Raw!H:H) -> 1655849.3 | D12: =SUM(Jobs_Clean[Invoice Amount]) -> 1655849.3 | E12: =C12-D12 -> 0 | F12: PASS | G12: =SUM(Jobs_Raw[Invoice Amount])
A13: Missing Invoice Amounts | B13: Jobs_Raw → Jobs_Clean | C13: 0 | D13: 2 | E13: 2 | F13: FLAGGED | G13: =COUNTBLANK(Jobs_Clean[Invoice Amount])
A14: Amount Paid Total | B14: Jobs_Raw → Jobs_Clean | C14: =SUM(Jobs_Raw!J:J) -> 1356106.5 | D14: =SUM(Jobs_Clean!J:J) -> 1356106.5 | E14: =C14-D14 -> 0 | F14: PASS | G14: =SUM(Jobs_Raw[Amount Paid]) | H14: 2 job records have missing Invoice Amounts; records retained for client review.
A15: Negative Invoice Amounts | B15: Jobs_Raw → Jobs_Clean | C15: 0 | D15: 2 | E15: 2 | F15: FLAGGED | G15: =COUNTIF(Jobs_Clean[Invoice Amount],"<0") | H15: 2 job records contain negative Invoice Amounts; records retained for client review.
A16: Payment Exceptions | B16: Jobs_Clean | C16: 0 | D16: 7 | E16: =D16-C16 -> 7 | F16: FLAGGED | G16: Payment Status / Amount Paid logic | H16: 7 job records have payment amounts that do not agree with the recorded Payment Status; records retained for client review.
A17: Service Type Coverage | B17: Jobs vs Services | C17: 0 Unmatched | D17: 0 Unmatched | E17: 0 | F17: PASS | G17: Lookup / Merge against Services_Clean | H17: All Job Service Types match the standardized Services master.
A21: CONTROL CONCLUSION
A22: Raw and clean record counts reconcile, and key data relationships and standardized Service Types have been validated. Financial values were preserved during cleaning. Known data-quality exceptions, including duplicate Job IDs, missing Client IDs, and payment exceptions, were retained and flagged rather than altered or removed. The cleaned dataset is suitable for Tier 1 KPI and business analysis based on the data provided.

Sheet Data_Quality
A1: CLEANSLATE CLEANING CO.
A2: Data Quality & Business Health Check
A4: DATA QUALITY SUMMARY
A5: Check | B5: Result | C5: Status | D5: Severity | E5: Source | F5: Notes / Interpretation
A6: Jobs — Total Rows | B6: 7500 | C6: INFO | D6: Info | E6: Jobs_Raw
A7: Jobs — Duplicate Job IDs | B7: 4 | C7: Error | D7: High | E7: Jobs_Raw | F7: 4 duplicate Job IDs were identified. The associated records contain different details, indicating a potential Job ID data-entry or assignment issue. Records were retained because the correct IDs cannot be determined from the available data.
A8: Jobs — Missing Client IDs | B8: 5 | C8: Warning | D8: Medium | E8: Jobs_Raw | F8: 5 job records have no Client ID, preventing reliable customer-level attribution.
A9: Jobs — Invalid Dates | B9: 1 | C9: Error | D9: High | E9: Jobs_Raw | F9: 1 job record contains an invalid date and cannot be reliably used for date-based analysis.
A10: Jobs — Future Dates | B10: 1 | C10: Warning | D10: Medium | E10: Jobs_Raw | F10: 1 job is dated in the future and should be reviewed before trend analysis.
A11: Jobs — Missing Invoice Amounts | B11: 2 | C11: Warning | D11: Medium | E11: Jobs_Raw | F11: 2 job records have no invoice amount, which affects revenue calculations.
A12: Jobs — Negative Invoice Amounts | B12: 2 | C12: Error | D12: High | E12: Jobs_Raw | F12: 2 job records contain negative invoice amounts and require investigation before calculating revenue.
A13: Jobs — Invalid Hours | B13: 2 | C13: Error | D13: Medium | E13: Jobs_Raw | F13: 2 job records contain invalid hours values and should be corrected or excluded from operational analysis.
A14: Jobs — Missing Cleaners | B14: 2 | C14: Warning | D14: Low | E14: Jobs_Raw | F14: 2 job records have no cleaner assigned, limiting cleaner-level analysis.
A15: Jobs — Payment Integrity Exceptions | B15: 7 | C15: Error | D15: High | E15: Jobs_Raw | F15: 7 job records have payment amounts that do not agree with the recorded Payment Status. These exceptions should be reviewed before relying on payment or revenue reporting.
A16: Customers — Duplicate Client IDs | B16: 0 | C16: PASS | D16: High | E16: Customers_Raw | F16: No duplicate Client IDs were identified in the customer table.
A17: Jobs — Orphan Client IDs | B17: 0 | C17: PASS | D17: High | E17: Jobs + Customers | F17: No Orphan Client IDs were identified in the customer table.
A18: Jobs — Unrecognized Service Types | B18: 2 | C18: Warning | D18: Medium | E18: Jobs + Services | F18: 2 service values do not match the standardized Services master list and require review.
A19: Text Standardization Issues | B19: Issues found | C19: Warning | D19: Low | E19: Jobs_Raw | F19: Inconsistent capitalization and spacing identified in Service Area, Cleaner names.
A22: DATA QUALITY CONCLUSION
A23: The CleanSlate dataset is suitable for Tier 1 KPI and business analysis after applying objective data standardization and cleanup. The review identified several data-quality exceptions, including duplicate Job IDs, missing Client IDs, an invalid date, future-dated activity, missing and negative invoice amounts, invalid hours, missing cleaner values, and payment-status inconsistencies. Objective formatting and standardization issues were corrected in the Clean data tables, including text formatting and non-standard Service Type values. Records containing business-data exceptions that could not be reliably corrected from the information provided were retained and flagged rather than deleted or altered. Validation and reconciliation confirmed that the cleaning process preserved the source record counts and financial values, and that nonblank Job Client IDs and standardized Service Types reconcile to their respective master tables. The cleaned dataset can therefore proceed to KPI and business analysis, with the documented data-quality exceptions taken into consideration when interpreting the results.

Sheet KPIs_Insights
A1: CLEANSLATE CLEANING CO.
A2: KPIs & Business Insights
A4: CORE KPIs
A5: Total Jobs | C5: Total Customers | E5: Total Invoiced Revenue | G5: Total Amount Paid | I5: Average Invoiced Revenue | K5: Average Hours Per Job
A6: =ROWS(Jobs_Clean[]) -> 7500 | C6: =ROWS(Customers_Clean[]) -> 1200 | E6: =SUM(Jobs_Clean[Invoice Amount]) -> 1655849.3 | G6: =SUM(Jobs_Clean[Amount Paid]) -> 1356106.5 | I6: =AVERAGE(Jobs_Clean[Invoice Amount]) -> 220.8388 | K6: =AVERAGE(Jobs_Clean[Hours]) -> 3.0081867
A10: REVENUE AND JOB ANALYSIS
A11: Service Type | B11: Revenue | C11: Jobs | E11: Service Area | F11: Revenue | G11: Jobs | I11: Payment Status | J11: Jobs | K11: Amount Paid
A12: Post-Construction Clean | B12: =VLOOKUP(A12, Analysis!$A$7:$B$12, 2, FALSE) -> 457782.31 | C12: =VLOOKUP(A12, Analysis!$A$7:$C$12, 3, FALSE) -> 1273 | E12: Leander | F12: =VLOOKUP(E12,Analysis!$E$7:$F$12, 2, FALSE) -> 285533.09 | G12: =VLOOKUP(E12, Analysis!$E$7:$G$12, 3, FALSE) -> 1291 | I12: Paid | J12: =VLOOKUP(I12, Analysis!$I$7:$K$9, 2, FALSE) -> 5388 | K12: =VLOOKUP(I12, Analysis!$I$7:$K$9, 3, FALSE) -> 1190506
A13: Move-Out Clean | B13: =VLOOKUP(A13, Analysis!$A$7:$B$12, 2, FALSE) -> 362831.08 | C13: =VLOOKUP(A13, Analysis!$A$7:$C$12, 3, FALSE) -> 1248 | E13: Round Rock | F13: =VLOOKUP(E13,Analysis!$E$7:$F$12, 2, FALSE) -> 281783.28 | G13: =VLOOKUP(E13, Analysis!$E$7:$G$12, 3, FALSE) -> 1281 | I13: Partial | J13: =VLOOKUP(I13, Analysis!$I$7:$K$9, 2, FALSE) -> 1373 | K13: =VLOOKUP(I13, Analysis!$I$7:$K$9, 3, FALSE) -> 165504.53
A14: Deep Clean | B14: =VLOOKUP(A14, Analysis!$A$7:$B$12, 2, FALSE) -> 291553 | C14: =VLOOKUP(A14, Analysis!$A$7:$C$12, 3, FALSE) -> 1265 | E14: North Austin | F14: =VLOOKUP(E14,Analysis!$E$7:$F$12, 2, FALSE) -> 279486.96 | G14: =VLOOKUP(E14, Analysis!$E$7:$G$12, 3, FALSE) -> 1246 | I14: Unpaid | J14: =VLOOKUP(I14, Analysis!$I$7:$K$9, 2, FALSE) -> 739 | K14: =VLOOKUP(I14, Analysis!$I$7:$K$9, 3, FALSE) -> 95.94
A15: Office Clean | B15: =VLOOKUP(A15, Analysis!$A$7:$B$12, 2, FALSE) -> 251223.97 | C15: =VLOOKUP(A15, Analysis!$A$7:$C$12, 3, FALSE) -> 1293 | E15: Cedar Park | F15: =VLOOKUP(E15,Analysis!$E$7:$F$12, 2, FALSE) -> 273183.12 | G15: =VLOOKUP(E15, Analysis!$E$7:$G$12, 3, FALSE) -> 1252
A16: Standard Clean | B16: =VLOOKUP(A16, Analysis!$A$7:$B$12, 2, FALSE) -> 157823.82 | C16: =VLOOKUP(A16, Analysis!$A$7:$C$12, 3, FALSE) -> 1228 | E16: Pflugerville | F16: =VLOOKUP(E16,Analysis!$E$7:$F$12, 2, FALSE) -> 268619.51 | G16: =VLOOKUP(E16, Analysis!$E$7:$G$12, 3, FALSE) -> 1227
A17: Recurring Clean | B17: =VLOOKUP(A17, Analysis!$A$7:$B$12, 2, FALSE) -> 134635.16 | C17: =VLOOKUP(A17, Analysis!$A$7:$C$12, 3, FALSE) -> 1193 | E17: Georgetown | F17: =VLOOKUP(E17,Analysis!$E$7:$F$12, 2, FALSE) -> 267243.38 | G17: =VLOOKUP(E17, Analysis!$E$7:$G$12, 3, FALSE) -> 1203
A20: CUSTOMER ACTIVITY ANALYSIS
A21: Customer Metric | B21: Value
A22: Repeat Customers | B22: =COUNTIF(Analysis!L20:L1217,">1")-1 -> 1182
A23: Repeat Customer % | B23: =B22/1200 -> 0.985
A26: BUSINESS FINDINGS
A27: 1. Post-Construction Clean is the strongest revenue-generating service
A28: Post-Construction Clean generated approximately $457,782 in invoiced revenue, representing about 27.6% of total invoiced revenue across 1,273 jobs.
A29: Business Implication: This service is the largest contributor to revenue and may warrant attention when considering service promotion, capacity, pricing, or growth opportunities.
A31: 2. Recurring Clean has high job volume but relatively low revenue per job
A32: Recurring Clean accounted for 1,193 jobs, but generated approximately $134,635 in invoiced revenue. Its average invoiced revenue per job is approximately $113, substantially lower than the other service categories.
A33: Business Implication: Recurring Clean provides meaningful workload volume, but its lower revenue per job suggests an opportunity to review pricing, service scope, labor requirements, or profitability.
A35: 3. Leander is the strongest service area
A36: Leander generated approximately $285,533 in invoiced revenue across 1,291 jobs, making it the leading service area by both revenue and job volume.
A37: Business Implication: Leander appears to be the strongest operating market in the provided data and may be worth considering for customer acquisition, staffing, or expansion efforts.
A39: 4. A significant portion of invoiced revenue has not been recorded as paid
A40: The dataset shows:
... A54: Note:The 5 jobs with missing Client IDs are excluded from customer-level attribution; they are retained and flagged separately in the Data Quality findings.

Sheet Analysis
A1: CLEANSLATE CLEANING CO.
A2: Jobs and Customer Analysis
A5: SERVICE PERFORMANCE | E5: SERVICE AREA PERFORMANCE | I5: PAYMENT PERFORMANCE
A6: Service Type | B6: Invoiced Revenue | C6: Number of Jobs | E6: Service Area | F6: Invoiced Revenue | G6: Number of Jobs | I6: Payment Status | J6: Number of Jobs | K6: Total Amount Paid
A7: Deep Clean | B7: 291553 | C7: 1265 | E7: Cedar Park | F7: 273183.12 | G7: 1252 | I7: Paid | J7: 5388 | K7: 1190506
A8: Move-Out Clean | B8: 362831.08 | C8: 1248 | E8: Georgetown | F8: 267243.38 | G8: 1203 | I8: Partial | J8: 1373 | K8: 165504.53
A9: Office Clean | B9: 251223.97 | C9: 1293 | E9: Leander | F9: 285533.09 | G9: 1291 | I9: Unpaid | J9: 739 | K9: 95.94
A10: Post-Construction Clean | B10: 457782.31 | C10: 1273 | E10: North Austin | F10: 279486.96 | G10: 1246 | I10: Grand Total | J10: 7500 | K10: 1356106.5
A11: Recurring Clean | B11: 134635.16 | C11: 1193 | E11: Pflugerville | F11: 268619.51 | G11: 1227
A12: Standard Clean | B12: 157823.82 | C12: 1228 | E12: Round Rock | F12: 281783.28 | G12: 1281
A13: Grand Total | B13: 1655849.3 | C13: 7500 | E13: Grand Total | F13: 1655849.3 | G13: 7500
A18: CLEANER WORKLOAD | F18: MONTHLY TREND | K18: CUSTOMER ACTIVITY
A19: Cleaners | B19: Number of Jobs | C19: Total Hours | D19: Invoiced Amount | F19: Years | G19: Job Date | H19: Invoiced Amount | I19: Number of Jobs | K19: Client ID | L19: Number of Jobs
A20: Aisha Khan | B20: 953 | C20: 2859.1 | D20: 212582.83 | F20: <1/1/2025 | G20: (blank) | H20: 388.68 | I20: 1 | K20: C0001 | L20: 3
A21: Daniel Brooks | B21: 939 | C21: 2823.1 | D21: 206275.3 | F21: 2025 | G21: Jan | H21: 144246.44 | I21: 653 | K21: C0002 | L21: 6
A22: Ethan Reed | B22: 920 | C22: 2790 | D22: 201306.88 | F22: 2025 | G22: Feb | H22: 118524.61 | I22: 561 | K22: C0003 | L22: 10
A23: James Carter | B23: 924 | C23: 2788.2 | D23: 202656.85 | F23: 2025 | G23: Mar | H23: 135270.13 | I23: 612 | K23: C0004 | L23: 6
A24: Marcus Green | B24: 957 | C24: 2831 | D24: 212446.16 | F24: 2025 | G24: Apr | H24: 126297.71 | I24: 570 | K24: C0005 | L24: 3
A25: Maria Lopez | B25: 958 | C25: 2913 | D25: 209558.74 | F25: 2025 | G25: May | H25: 140173.64 | I25: 635 | K25: C0006 | L25: 2
A26: Nina Patel | B26: 950 | C26: 2850.1 | D26: 211384.41 | F26: 2025 | G26: Jun | H26: 133053.46 | I26: 604 | K26: C0007 | L26: 6
A27: Sofia Martinez | B27: 897 | C27: 2700.4 | D27: 199139.13 | F27: 2025 | G27: Jul | H27: 141062.85 | I27: 664 | K27: C0008 | L27: 10
A28: (blank) | B28: 2 | C28: 6.5 | D28: 499.04 | F28: 2025 | G28: Aug | H28: 142881.82 | I28: 648 | K28: C0009 | L28: 8
A29: Grand Total | B29: 7500 | C29: 22561.4 | D29: 1655849.3 | F29: 2025 | G29: Sep | H29: 139121.28 | I29: 616 | K29: C0010 | L29: 7
F30: 2025 | G30: Oct | H30: 147473.61 | I30: 655 | K30: C0011 | L30: 6
F31: 2025 | G31: Nov | H31: 142620.39 | I31: 645 | K31: C0012 | L31: 5
F32: 2025 | G32: Dec | H32: 144488.67 | I32: 635 | K32: C0013 | L32: 3
F33: 2027 | G33: Dec | H33: 246.05 | I33: 1 | K33: C0014 | L33: 9
F34: Grand Total | H34: 1655849.3 | I34: 7500 | K34: C0015 | L34: 9
K35: C0016 | L35: 3
K36: C0017 | L36: 9
K37: C0018 | L37: 8
K38: C0019 | L38: 6
K39: C0020 | L39: 2
K40: C0021 | L40: 10
K41: C0022 | L41: 8
K42: C0023 | L42: 9
K43: C0024 | L43: 4
K44: C0025 | L44: 6
K45: C0026 | L45: 4
K46: C0027 | L46: 10
...

Sheet Jobs_Clean
A1: Job ID | B1: Job Date | C1: Client ID | D1: Service Type | E1: Service Area | F1: Cleaner | G1: Hours | H1: Invoice Amount | I1: Payment Status | J1: Amount Paid
A2: J00001 | B2: 45713 | C2: C0003 | D2: Standard Clean | E2: Leander | F2: Marcus Green | G2: 2.7 | H2: 144.95 | I2: Paid | J2: 144.95
A3: J00002 | B3: 45851 | C3: C0720 | D3: Recurring Clean | E3: Leander | F3: James Carter | G3: 1 | H3: 125.41 | I3: Partial | J3: 74.85
A4: J00003 | B4: 46009 | C4: C0462 | D4: Deep Clean | E4: Leander | F4: James Carter | G4: 3.1 | H4: 192.83 | I4: Paid | J4: 192.83
A5: J00004 | B5: 45711 | C5: C0152 | D5: Move-Out Clean | E5: Cedar Park | F5: Nina Patel | G5: 2.8 | H5: 258.3 | I5: Paid | J5: 258.3
A6: J00005 | B6: 45705 | C6: C0693 | D6: Recurring Clean | E6: Georgetown | F6: Marcus Green | G6: 2.7 | H6: 118.66 | I6: Paid | J6: 118.66
A7: J00006 | B7: 45880 | C7: C0322 | D7: Standard Clean | E7: North Austin | F7: Ethan Reed | G7: 2.1 | H7: 115.24 | I7: Paid | J7: 115.24
A8: J00007 | B8: 46014 | C8: C1135 | D8: Post-Construction Clean | E8: Pflugerville | F8: Sofia Martinez | G8: 2.6 | H8: 309.25 | I8: Paid | J8: 309.25
A9: J00008 | B9: 45939 | C9: C1006 | D9: Deep Clean | E9: North Austin | F9: Ethan Reed | G9: 2.4 | H9: 191.55 | I9: Paid | J9: 191.55
A10: J00009 | B10: 45996 | C10: C0984 | D10: Deep Clean | E10: North Austin | F10: Maria Lopez | G10: 3.3 | H10: 268.19 | I10: Paid | J10: 268.19
A11: J00010 | B11: 45717 | C11: C0632 | D11: Office Clean | E11: Leander | F11: Marcus Green | G11: 4.2 | H11: 221.01 | I11: Paid | J11: 221.01
A12: J00011 | B12: 45986 | C12: C1115 | D12: Office Clean | E12: Cedar Park | F12: Ethan Reed | G12: 3.7 | H12: 191.14 | I12: Paid | J12: 191.14
A13: J00012 | B13: 45896 | C13: C0540 | D13: Deep Clean | E13: Round Rock | F13: Maria Lopez | G13: 2.4 | H13: 203.15 | I13: Paid | J13: 203.15
... A511: J00510 | B511: 45944 | C511: C0085 | D511: Recurring Clean | E511: Cedar Park | F511: Sofia Martinez | G511: 3.9 | H511: 100.04 | I511: Paid | J511: 100.04
A512: J00511 | B512: 45831 | D512: Deep Clean | E512: North Austin | F512: Ethan Reed | G512: 2.8 | H512: 211.76 | I512: Paid | J512: 211.76
A513: J00512 | B513: 45723 | C513: C1023 | D513: Move-Out Clean | E513: Pflugerville | F513: Ethan Reed | G513: 2.1 | H513: 334.64 | I513: Paid | J513: 334.64
A514: J00513 | B514: 45792 | C514: C0541 | D514: Recurring Clean | E514: Round Rock | F514: Nina Patel | G514: 3.6 | H514: 131.79 | I514: Partial | J514: 44.91
A515: J00514 | B515: 45994 | C515: C0902 | D515: Standard Clean | E515: Cedar Park | F515: Aisha Khan | G515: 2.5 | H515: 108.64 | I515: Paid | J515: 108.64
A516: J00515 | B516: 45898 | C516: C0533 | D516: Deep Clean | E516: Pflugerville | F516: Marcus Green | G516: 1 | H516: 264.27 | I516: Paid | J516: 264.27
A517: J00516 | B517: 45840 | C517: C1149 | D517: Office Clean | E517: Leander | F517: Marcus Green | G517: 4.1 | H517: 168.98 | I517: Paid | J517: 168.98
A518: J00517 | B518: 45733 | C518: C0254 | D518: Move-Out Clean | E518: North Austin | F518: Daniel Brooks | G518: 3.4 | H518: 259.04 | I518: Paid | J518: 259.04
A519: J00518 | B519: 45797 | C519: C1154 | D519: Post-Construction Clean | E519: Georgetown | F519: Daniel Brooks | G519: 2.6 | H519: 368.98 | I519: Unpaid | J519: 0
A520: J00519 | B520: 45927 | C520: C1169 | D520: Deep Clean | E520: Leander | F520: James Carter | G520: 3 | H520: 198.68 | I520: Paid | J520: 198.68
A521: J00520 | B521: 45803 | C521: C0250 | D521: Office Clean | E521: Round Rock | F521: James Carter | G521: 4.1 | H521: 217.16 | I521: Paid | J521: 217.16
A522: J00521 | B522: 45699 | C522: C0943 | D522: Post-Construction Clean | E522: Pflugerville | F522: Marcus Green | G522: 1 | H522: 370.29 | I522: Paid | J522: 370.29
A523: J00522 | B523: 45680 | C523: C0928 | D523: Move-Out Clean | E523: Pflugerville | F523: Aisha Khan | G523: 3.6 | H523: 263.33 | I523: Paid | J523: 263.33
A524: J00523 | B524: 45987 | C524: C0580 | D524: Move-Out Clean | E524: North Austin | F524: James Carter | G524: 1.8 | H524: 251.48 | I524: Paid | J524: 251.48
... A1778: J01777 | B1778: 45909 | C1778: C0296 | D1778: Office Clean | E1778: Pflugerville | F1778: Daniel Brooks | G1778: 1.3 | H1778: 213.96 | I1778: Paid | J1778: 213.96
A1779: J01778 | B1779: 45807 | D1779: Deep Clean | E1779: Pflugerville | F1779: Maria Lopez | G1779: 3.9 | H1779: 201.47 | I1779: Partial | J1779: 169.41
A1780: J01779 | B1780: 46018 | C1780: C0344 | D1780: Move-Out Clean | E1780: Round Rock | F1780: Daniel Brooks | G1780: 3.3 | H1780: 264.04 | I1780: Partial | J1780: 178.11
A1781: J01780 | B1781: 45712 | C1781: C0274 | D1781: Deep Clean | E1781: North Austin | F1781: Aisha Khan | G1781: 2.9 | H1781: 207.01 | I1781: Paid | J1781: 207.01
A1782: J01781 | B1782: 45988 | C1782: C0015 | D1782: Post-Construction Clean | E1782: Round Rock | F1782: James Carter | G1782: 4.4 | H1782: 405.97 | I1782: Paid | J1782: 405.97
A1783: J01782 | B1783: 45870 | C1783: C0538 | D1783: Office Clean | E1783: Cedar Park | F1783: Daniel Brooks | G1783: 3.5 | H1783: 209.22 | I1783: Paid | J1783: 209.22
A1784: J01783 | B1784: 45670 | C1784: C1091 | D1784: Deep Clean | E1784: Leander | F1784: Nina Patel | G1784: 2.6 | H1784: 227.16 | I1784: Partial | J1784: 179.44
A1785: J01784 | B1785: 45903 | C1785: C0951 | D1785: Move-Out Clean | E1785: Round Rock | F1785: Ethan Reed | G1785: 3 | H1785: 298.31 | I1785: Paid | J1785: 298.31
A1786: J01785 | B1786: 45727 | C1786: C0777 | D1786: Deep Clean | E1786: Georgetown | F1786: Maria Lopez | G1786: 2.4 | H1786: 231.49 | I1786: Partial | J1786: 150.9
A1787: J01786 | B1787: 45890 | C1787: C0784 | D1787: Post-Construction Clean | E1787: Georgetown | F1787: Daniel Brooks | G1787: 4.1 | H1787: 386.87 | I1787: Paid | J1787: 386.87
A1788: J01787 | B1788: 45939 | C1788: C0373 | D1788: Post-Construction Clean | E1788: Leander | F1788: James Carter | G1788: 2.7 | H1788: 353.5 | I1788: Paid | J1788: 353.5
A1789: J01788 | B1789: 45884 | C1789: C0445 | D1789: Recurring Clean | E1789: Pflugerville | F1789: Aisha Khan | G1789: 2.6 | H1789: 130.33 | I1789: Unpaid | J1789: 0
A1790: J01789 | B1790: 45824 | C1790: C0373 | D1790: Deep Clean | E1790: Cedar Park | F1790: Daniel Brooks | G1790: 2.9 | H1790: 266.48 | I1790: Partial | J1790: 194.43
...

Sheet Customers_Clean
A1: Client ID | B1: Client Name | C1: Service Area | D1: Customer Type
A2: C0001 | B2: Riverbend Dental 0001 | C2: North Austin | D2: Commercial
A3: C0002 | B3: Sunset Apartments 0002 | C3: Cedar Park | D3: Residential
A4: C0003 | B4: Riverbend Dental 0003 | C4: Pflugerville | D4: Residential
A5: C0004 | B5: Maple Street Bakery 0004 | C5: Leander | D5: Residential
A6: C0005 | B6: Oak & Pine Home 0005 | C6: North Austin | D6: Residential
A7: C0006 | B7: Sunset Apartments 0006 | C7: Georgetown | D7: Residential
A8: C0007 | B8: Northline Design 0007 | C8: Cedar Park | D8: Commercial
A9: C0008 | B9: Sunset Apartments 0008 | C9: Leander | D9: Commercial
A10: C0009 | B10: Oak & Pine Home 0009 | C10: Cedar Park | D10: Commercial
A11: C0010 | B11: Willow Creek Family 0010 | C11: Round Rock | D11: Residential
A12: C0011 | B12: Sunset Apartments 0011 | C12: Round Rock | D12: Residential
... A1201: C1200 | B1201: Riverbend Dental 1200 | C1201: Round Rock | D1201: Commercial

Sheet Services_Clean
A1: Service Code | B1: Service Type | C1: Standard Price
A2: CLN01 | B2: Standard Clean | C2: 125
A3: CLN02 | B3: Deep Clean | C3: 225
A4: CLN03 | B4: Move-Out Clean | C4: 285
A5: CLN04 | B5: Office Clean | C5: 190
A6: CLN05 | B6: Recurring Clean | C6: 110
A7: CLN06 | B7: Post-Construction Clean | C7: 350

Sheet Jobs_Raw
A1: Job ID | B1: Job Date | C1: Client ID | D1: Service Type | E1: Service Area | F1: Cleaner | G1: Hours | H1: Invoice Amount | I1: Payment Status | J1: Amount Paid
A2: J00001 | B2: 45713 | C2: C0003 | D2: Standard Clean | E2: Leander | F2: Marcus Green | G2: 2.7 | H2: 144.95 | I2: Paid | J2: 144.95
A3: J00002 | B3: 45851 | C3: C0720 | D3: Recurring Clean | E3: Leander | F3: James Carter | G3: 1 | H3: 125.41 | I3: Partial | J3: 74.85
A4: J00003 | B4: 46009 | C4: C0462 | D4: Deep Clean | E4: Leander | F4: James Carter | G4: 3.1 | H4: 192.83 | I4: Paid | J4: 192.83
A5: J00004 | B5: 45711 | C5: C0152 | D5: Move-Out Clean | E5: Cedar Park | F5: Nina Patel | G5: 2.8 | H5: 258.3 | I5: Paid | J5: 258.3
A6: J00005 | B6: 45705 | C6: C0693 | D6: Recurring Clean | E6: Georgetown | F6: Marcus Green | G6: 2.7 | H6: 118.66 | I6: Paid | J6: 118.66
A7: J00006 | B7: 45880 | C7: C0322 | D7: Standard Clean | E7: North Austin | F7: Ethan Reed | G7: 2.1 | H7: 115.24 | I7: Paid | J7: 115.24
A8: J00007 | B8: 46014 | C8: C1135 | D8: Post-Construction Clean | E8: Pflugerville | F8: Sofia Martinez | G8: 2.6 | H8: 309.25 | I8: Paid | J8: 309.25
A9: J00008 | B9: 45939 | C9: C1006 | D9: Deep Clean | E9: North Austin | F9: Ethan Reed | G9: 2.4 | H9: 191.55 | I9: Paid | J9: 191.55
A10: J00009 | B10: 45996 | C10: C0984 | D10: Deep Clean | E10: North Austin | F10: Maria Lopez | G10: 3.3 | H10: 268.19 | I10: Paid | J10: 268.19
A11: J00010 | B11: 45717 | C11: C0632 | D11: Office Clean | E11: Leander | F11: Marcus Green | G11: 4.2 | H11: 221.01 | I11: Paid | J11: 221.01
A12: J00011 | B12: 45986 | C12: C1115 | D12: Office Clean | E12: Cedar Park | F12: Ethan Reed | G12: 3.7 | H12: 191.14 | I12: Paid | J12: 191.14
A13: J00012 | B13: 45896 | C13: C0540 | D13: Deep Clean | E13: Round Rock | F13: Maria Lopez | G13: 2.4 | H13: 203.15 | I13: Paid | J13: 203.15
... A511: J00510 | B511: 45944 | C511: C0085 | D511: Recurring Clean | E511: Cedar Park | F511: Sofia Martinez | G511: 3.9 | H511: 100.04 | I511: Paid | J511: 100.04
A512: J00511 | B512: 45831 | D512: Deep Clean | E512: North Austin | F512: Ethan Reed | G512: 2.8 | H512: 211.76 | I512: Paid | J512: 211.76
A513: J00512 | B513: 45723 | C513: C1023 | D513: Move-Out Clean | E513: Pflugerville | F513: Ethan Reed | G513: 2.1 | H513: 334.64 | I513: Paid | J513: 334.64
A514: J00513 | B514: 45792 | C514: C0541 | D514: Recurring Clean | E514: Round Rock | F514: Nina Patel | G514: 3.6 | H514: 131.79 | I514: Partial | J514: 44.91
A515: J00514 | B515: 45994 | C515: C0902 | D515: Standard Clean | E515: Cedar Park | F515: Aisha Khan | G515: 2.5 | H515: 108.64 | I515: Paid | J515: 108.64
A516: J00515 | B516: 45898 | C516: C0533 | D516: Deep Clean | E516: Pflugerville | F516: Marcus Green | G516: 1 | H516: 264.27 | I516: Paid | J516: 264.27
A517: J00516 | B517: 45840 | C517: C1149 | D517: Office Clean | E517: Leander | F517: Marcus Green | G517: 4.1 | H517: 168.98 | I517: Paid | J517: 168.98
A518: J00517 | B518: 45733 | C518: C0254 | D518: Move-Out Clean | E518: North Austin | F518: Daniel Brooks | G518: 3.4 | H518: 259.04 | I518: Paid | J518: 259.04
A519: J00518 | B519: 45797 | C519: C1154 | D519: Post-Construction Clean | E519: Georgetown | F519: Daniel Brooks | G519: 2.6 | H519: 368.98 | I519: Unpaid | J519: 0
A520: J00519 | B520: 45927 | C520: C1169 | D520: Deep Clean | E520: Leander | F520: James Carter | G520: 3 | H520: 198.68 | I520: Paid | J520: 198.68
A521: J00520 | B521: 45803 | C521: C0250 | D521: Office Clean | E521: Round Rock | F521: James Carter | G521: 4.1 | H521: 217.16 | I521: Paid | J521: 217.16
A522: J00521 | B522: 45699 | C522: C0943 | D522: Post-Construction Clean | E522: Pflugerville | F522: Marcus Green | G522: 1 | H522: 370.29 | I522: Paid | J522: 370.29
A523: J00522 | B523: 45680 | C523: C0928 | D523: Move-Out Clean | E523: Pflugerville | F523: Aisha Khan | G523: 3.6 | H523: 263.33 | I523: Paid | J523: 263.33
A524: J00523 | B524: 45987 | C524: C0580 | D524: Move-Out Clean | E524: North Austin | F524: James Carter | G524: 1.8 | H524: 251.48 | I524: Paid | J524: 251.48
... A1778: J01777 | B1778: 45909 | C1778: C0296 | D1778: Office Clean | E1778: Pflugerville | F1778: Daniel Brooks | G1778: 1.3 | H1778: 213.96 | I1778: Paid | J1778: 213.96
A1779: J01778 | B1779: 45807 | D1779: Deep Clean | E1779: Pflugerville | F1779: Maria Lopez | G1779: 3.9 | H1779: 201.47 | I1779: Partial | J1779: 169.41
A1780: J01779 | B1780: 46018 | C1780: C0344 | D1780: Move-Out Clean | E1780: Round Rock | F1780: Daniel Brooks | G1780: 3.3 | H1780: 264.04 | I1780: Partial | J1780: 178.11
A1781: J01780 | B1781: 45712 | C1781: C0274 | D1781: Deep Clean | E1781: North Austin | F1781: Aisha Khan | G1781: 2.9 | H1781: 207.01 | I1781: Paid | J1781: 207.01
A1782: J01781 | B1782: 45988 | C1782: C0015 | D1782: Post-Construction Clean | E1782: Round Rock | F1782: James Carter | G1782: 4.4 | H1782: 405.97 | I1782: Paid | J1782: 405.97
A1783: J01782 | B1783: 45870 | C1783: C0538 | D1783: Office Clean | E1783: Cedar Park | F1783: Daniel Brooks | G1783: 3.5 | H1783: 209.22 | I1783: Paid | J1783: 209.22
A1784: J01783 | B1784: 45670 | C1784: C1091 | D1784: Deep Clean | E1784: Leander | F1784: Nina Patel | G1784: 2.6 | H1784: 227.16 | I1784: Partial | J1784: 179.44
A1785: J01784 | B1785: 45903 | C1785: C0951 | D1785: Move-Out Clean | E1785: Round Rock | F1785: Ethan Reed | G1785: 3 | H1785: 298.31 | I1785: Paid | J1785: 298.31
A1786: J01785 | B1786: 45727 | C1786: C0777 | D1786: Deep Clean | E1786: Georgetown | F1786: Maria Lopez | G1786: 2.4 | H1786: 231.49 | I1786: Partial | J1786: 150.9
A1787: J01786 | B1787: 45890 | C1787: C0784 | D1787: Post-Construction Clean | E1787: Georgetown | F1787: Daniel Brooks | G1787: 4.1 | H1787: 386.87 | I1787: Paid | J1787: 386.87
A1788: J01787 | B1788: 45939 | C1788: C0373 | D1788: Post-Construction Clean | E1788: Leander | F1788: James Carter | G1788: 2.7 | H1788: 353.5 | I1788: Paid | J1788: 353.5
A1789: J01788 | B1789: 45884 | C1789: C0445 | D1789: Recurring Clean | E1789: Pflugerville | F1789: Aisha Khan | G1789: 2.6 | H1789: 130.33 | I1789: Unpaid | J1789: 0
A1790: J01789 | B1790: 45824 | C1790: C0373 | D1790: Deep Clean | E1790: Cedar Park | F1790: Daniel Brooks | G1790: 2.9 | H1790: 266.48 | I1790: Partial | J1790: 194.43
...

Sheet Customers_Raw
A1: Client ID | B1: Client Name | C1: Service Area | D1: Customer Type
A2: C0001 | B2: Riverbend Dental 0001 | C2: North Austin | D2: Commercial
A3: C0002 | B3: Sunset Apartments 0002 | C3: Cedar Park | D3: Residential
A4: C0003 | B4: Riverbend Dental 0003 | C4: Pflugerville | D4: Residential
A5: C0004 | B5: Maple Street Bakery 0004 | C5: Leander | D5: Residential
A6: C0005 | B6: Oak & Pine Home 0005 | C6: North Austin | D6: Residential
A7: C0006 | B7: Sunset Apartments 0006 | C7: Georgetown | D7: Residential
A8: C0007 | B8: Northline Design 0007 | C8: Cedar Park | D8: Commercial
A9: C0008 | B9: Sunset Apartments 0008 | C9: Leander | D9: Commercial
A10: C0009 | B10: Oak & Pine Home 0009 | C10: Cedar Park | D10: Commercial
A11: C0010 | B11: Willow Creek Family 0010 | C11: Round Rock | D11: Residential
A12: C0011 | B12: Sunset Apartments 0011 | C12: Round Rock | D12: Residential
... A1201: C1200 | B1201: Riverbend Dental 1200 | C1201: Round Rock | D1201: Commercial

Sheet Services_Raw
A1: Service Code | B1: Service Type | C1: Standard Price
A2: CLN01 | B2: Standard Clean | C2: 125
A3: CLN02 | B3: Deep Clean | C3: 225
A4: CLN03 | B4: Move-Out Clean | C4: 285
A5: CLN04 | B5: Office Clean | C5: 190
A6: CLN05 | B6: Recurring Clean | C6: 110
A7: CLN06 | B7: Post-Construction Clean | C7: 350

Sheet File_ReadMe
A1: CLEANSLATE CLEANING CO.
A2: File_ReadMe
A3: Section | B3: Details
A5: Project | B5: CleanSlate Cleaning Co. — Tier 1 Data Cleanup & Business Data Health Check
A6: Purpose | B6: Demonstrate an end-to-end small-business data cleanup, validation, analysis, and reporting workflow.
A7: Data Type | B7: Synthetic/fictitious data created specifically for portfolio and demonstration purposes. No real client data is used.
A8: Engagement | B8: Tier 1 — Data Cleanup & Business Data Health Check
A9: Source Data | B9: Jobs_Raw, Customers_Raw, Services_Raw
A10: Workflow | B10: Raw Data → Diagnose → Clean → Validate & Reconcile → Data Quality Conclusion → Analyze → Report
A11: Clean Data | B11: Jobs_Clean, Customers_Clean, Services_Clean
A12: Data Quality | B12: Documents missing, invalid, duplicate, inconsistent, and other data-quality conditions identified during the review.
A13: Validation & Reconciliation | B13: Confirms that record counts and key financial values were preserved and that important relationships and standardized values reconcile.
A14: Analysis | B14: Core KPIs plus service performance, service area performance, payment performance, monthly trends, cleaner workload, and customer frequency analysis.
A15: Business Findings | B15: Identifies key revenue, service, geographic, payment, and customer-pattern findings supported by the data.
... A21: Report Date | B21: 10/1/2026
A25: How to Navigate This Workbook
A26: 1. Dashboard — Executive-level business and data-health snapshot. 2. Client_Summary — Key findings, KPIs, and recommendations. 3. Client_Brief — Engagement overview and context. 4. Data_Quality — Detailed data-quality checks and overall conclusion. 5. Validation_Reconciliation — Data preservation and relationship controls. 6. KPIs_Insights — Core KPIs and business findings. 7. Analysis — Supporting PivotTables and analysis. 8. Jobs_Clean / Customers_Clean / Services_Clean — Cleaned source tables. 9. Jobs_Raw / Customers_Raw / Services_Raw — Original source data. 10. File_ReadMe — Workbook documentation and navigation guide.
